<mujoco>
	<option>integrator = "RK4" <flag energy = "enable" contact = "disable"/>
	
	</option>
	<worldbody>
        <light diffuse=".5 .5 .5" pos="0 0 20" dir="0 0 -1"/>
		<geom type="plane" size="6 6 0.1" rgba=".9 0 0 1"/>
		<camera pos = "3 -7 0"/>
		<body name ="mc"pos="0 0 2.5" >

			<geom type="box" size=".1 .1 .1" rgba=".5  1 1 1" mass="0.5"/>
			<joint name = "x sliding joint " type = "slide" pos = "0 0 0 " axis = "1 0 0 "/>
			<joint name = "y sliding joint " type = "slide" pos = "0 0 0 " axis = "0 1 0 "/>
			<body name ="mass 1"pos="0 0 0" euler="0 0 0">
				<geom type="cylinder" size="0.05 .5" rgba="0 .9 0 1" fromto = "0 0 0 0 0 -1"/>
				<inertial pos = "0 0 -.5" mass = "1" diaginertia = "0.083958 0.083958  0.00125"/>
				<joint name="pin" type="hinge" axis = "0 1 0" pos="0 0 0"/>
					<body name ="mass 2 " pos="0 0  -1" euler="0 0 0">
						<geom type="cylinder" size="0.05 .5" rgba="0 0 .9 1" fromto = "0 0 0 0 0 -1"/>
						<inertial pos = "0 0 -.5" mass = "1" diaginertia = "0.083958 0.083958 0.00125"/>
						<joint name="pin2" type="hinge" axis = "1 0 0" pos="0 0 0"/>
					</body>
			</body>
		</body>
	</worldbody>
	<!--<actuator>
		<cylinder joint = "z joint" name = "z cylinder " ctrllimited="true" ctrlrange="19.62 25"/>
	</actuator>-->
	<!-- <actuator>
		<motor joint="pin" name="torque" gear="1" ctrllimited="true" ctrlrange="-100 100" />
		<position name="position_servo" joint="pin" kp="10" />
		<velocity name="velocity_servo" joint="pin" kv="0" />
	</actuator> -->
	<sensor>
		<jointpos joint="pin" />
		<jointpos joint="pin2"/>
	</sensor>
</mujoco>
